Workbook

Sheet output_sheet
A1: 指标 (Metric) | C1: 深圳 (Shenzhen) | D1: 香港 (Hong Kong) | E1: 旧金山湾区 (SF Bay Area)
A2: 最新数据时间 | C2: =_xlfn.XLOOKUP(MAX(Processed_CN_SZ[Date]), Processed_CN_SZ[Date], Processed_CN_SZ[Date]) -> 46174 | D2: =_xlfn.XLOOKUP(MAX(Processed_CN_HK[Date]), Processed_CN_HK[Date], Processed_CN_HK[Date]) -> 46113 | E2: =_xlfn.XLOOKUP(MAX(Processed_US_CA[Date]), Processed_US_CA[Date], Processed_US_CA[Date]) -> 46082
A3: 房价指数 | B3: 2020=100 | C3: {=ROUND(_xlfn.XLOOKUP(MAX(Processed_CN_SZ[Date]), Processed_CN_SZ[Date], Processed_CN_SZ[Value]) / AVERAGE(_xlfn._xlws.FILTER(Processed_CN_SZ[Value], YEAR(Processed_CN_SZ[Date])=2020)), 3) * 100} -> 93.6 | D3: {=ROUND(_xlfn.XLOOKUP(MAX(Processed_CN_HK[Date]), Processed_CN_HK[Date], Processed_CN_HK[Value]) / AVERAGE(_xlfn._xlws.FILTER(Processed_CN_HK[Value], YEAR(Processed_CN_HK[Date])=2020)), 3) * 100} -> 83.1 | E3: {=ROUND(_xlfn.XLOOKUP(MAX(Processed_US_CA[Date]), Processed_US_CA[Date], Processed_US_CA[Value]) / AVERAGE(_xlfn._xlws.FILTER(Processed_US_CA[Value], YEAR(Processed_US_CA[Date])=2020)), 3) * 100} -> 129.1
B4: 上月=100 | C4: =_xlfn.XLOOKUP(MAX(Processed_CN_SZ[Date]), Processed_CN_SZ[Date], Processed_CN_SZ[上月=100]) -> 99.746115 | D4: =_xlfn.XLOOKUP(MAX(Processed_CN_HK[Date]), Processed_CN_HK[Date], Processed_CN_HK[上月=100]) -> 101.21483 | E4: =_xlfn.XLOOKUP(MAX(Processed_US_CA[Date]), Processed_US_CA[Date], Processed_US_CA[上月=100]) -> 99.643246
B5: 上年同月=100 | C5: =_xlfn.XLOOKUP(MAX(Processed_CN_SZ[Date]), Processed_CN_SZ[Date], Processed_CN_SZ[上年同月=100]) -> 91.736306 | D5: =_xlfn.XLOOKUP(MAX(Processed_CN_HK[Date]), Processed_CN_HK[Date], Processed_CN_HK[上年同月=100]) -> 110.50611 | E5: =_xlfn.XLOOKUP(MAX(Processed_US_CA[Date]), Processed_US_CA[Date], Processed_US_CA[上年同月=100]) -> 100.47197
B6: YoY (%) | C6: =_xlfn.XLOOKUP(MAX(Processed_CN_SZ[Date]), Processed_CN_SZ[Date], Processed_CN_SZ[YoY]) -> -0.082636938 | D6: =_xlfn.XLOOKUP(MAX(Processed_CN_HK[Date]), Processed_CN_HK[Date], Processed_CN_HK[YoY]) -> 0.10506108 | E6: =_xlfn.XLOOKUP(MAX(Processed_US_CA[Date]), Processed_US_CA[Date], Processed_US_CA[YoY]) -> 0.0047197258
B7: MoM (%) | C7: =_xlfn.XLOOKUP(MAX(Processed_CN_SZ[Date]), Processed_CN_SZ[Date], Processed_CN_SZ[MoM]) -> -0.0025388463 | D7: =_xlfn.XLOOKUP(MAX(Processed_CN_HK[Date]), Processed_CN_HK[Date], Processed_CN_HK[MoM]) -> 0.012148338 | E7: =_xlfn.XLOOKUP(MAX(Processed_US_CA[Date]), Processed_US_CA[Date], Processed_US_CA[MoM]) -> -0.0035675381
B8: YTD (%) | C8: =_xlfn.XLOOKUP(MAX(Processed_CN_SZ[Date]), Processed_CN_SZ[Date], Processed_CN_SZ[YTD(%)]) -> -0.021296123 | D8: =_xlfn.XLOOKUP(MAX(Processed_CN_HK[Date]), Processed_CN_HK[Date], Processed_CN_HK[YTD(%)]) -> 0.044884488 | E8: =_xlfn.XLOOKUP(MAX(Processed_US_CA[Date]), Processed_US_CA[Date], Processed_US_CA[YTD(%)]) -> -0.0022773766
A9: 租金指数 | B9: 2020=100 | C9: - | D9: {=ROUND(_xlfn.XLOOKUP(MAX(Processed_RentPrice_CN_HK__2[Date]), Processed_RentPrice_CN_HK__2[Date], Processed_RentPrice_CN_HK__2[Value]) / AVERAGE(_xlfn._xlws.FILTER(Processed_RentPrice_CN_HK__2[Value], YEAR(Processed_RentPrice_CN_HK__2[Date])=2020)), 3) * 100} -> 112.8 | E9: {=ROUND(_xlfn.XLOOKUP(MAX(Processed_RentPrice_US_CA__2[Date]), Processed_RentPrice_US_CA__2[Date], Processed_RentPrice_US_CA__2[Value]) / AVERAGE(_xlfn._xlws.FILTER(Processed_RentPrice_US_CA__2[Value], YEAR(Processed_RentPrice_US_CA__2[Date])=2020)), 3) * 100} -> 113.9
B10: 上月=100 | C10: - | D10: =_xlfn.XLOOKUP(MAX(Processed_RentPrice_CN_HK__2[Date]), Processed_RentPrice_CN_HK__2[Date], Processed_RentPrice_CN_HK__2[上月=100]) -> 100.59347 | E10: =_xlfn.XLOOKUP(MAX(Processed_RentPrice_US_CA__2[Date]), Processed_RentPrice_US_CA__2[Date], Processed_RentPrice_US_CA__2[上月=100]) -> 100.7585
B11: 上年同月=100 | C11: - | D11: =_xlfn.XLOOKUP(MAX(Processed_RentPrice_CN_HK__2[Date]), Processed_RentPrice_CN_HK__2[Date], Processed_RentPrice_CN_HK__2[上年同月=100]) -> 104.89943 | E11: =_xlfn.XLOOKUP(MAX(Processed_RentPrice_US_CA__2[Date]), Processed_RentPrice_US_CA__2[Date], Processed_RentPrice_US_CA__2[上年同月=100]) -> 102.6597
B12: YoY (%) | C12: - | D12: =_xlfn.XLOOKUP(MAX(Processed_RentPrice_CN_HK__2[Date]), Processed_RentPrice_CN_HK__2[Date], Processed_RentPrice_CN_HK__2[YoY]) -> 0.048994327 | E12: =_xlfn.XLOOKUP(MAX(Processed_RentPrice_US_CA__2[Date]), Processed_RentPrice_US_CA__2[Date], Processed_RentPrice_US_CA__2[YoY]) -> 0.026597038
B13: MoM (%) | C13: - | D13: =_xlfn.XLOOKUP(MAX(Processed_RentPrice_CN_HK__2[Date]), Processed_RentPrice_CN_HK__2[Date], Processed_RentPrice_CN_HK__2[MoM]) -> 0.0059347181 | E13: =_xlfn.XLOOKUP(MAX(Processed_RentPrice_US_CA__2[Date]), Processed_RentPrice_US_CA__2[Date], Processed_RentPrice_US_CA__2[MoM]) -> 0.0075850095
B14: YTD (%) | C14: - | D14: =_xlfn.XLOOKUP(MAX(Processed_RentPrice_CN_HK__2[Date]), Processed_RentPrice_CN_HK__2[Date], Processed_RentPrice_CN_HK__2[YTD(%)]) -> 0.012948207 | E14: =_xlfn.XLOOKUP(MAX(Processed_RentPrice_US_CA__2[Date]), Processed_RentPrice_US_CA__2[Date], Processed_RentPrice_US_CA__2[YTD(%)]) -> 0.010930872
A15: 当前房价 | C15: - | D15: ='price-to-rent ratio'!H3 -> 182317 | E15: ='price-to-rent ratio'!I3 -> 1369171
A16: 当前月租金 | C16: - | D16: ='price-to-rent ratio'!H6 -> 421 | E16: ='price-to-rent ratio'!I6 -> 4000
A17: 租售比 | C17: ='price-to-rent ratio'!G7 -> 0.019534039 | D17: ='price-to-rent ratio'!H7 -> 0.027709978 | E17: ='price-to-rent ratio'!I7 -> 0.03505771
A18: 数据源 | C18: 国家统计局 (NBS)，深圳市住房和建设局|深圳市房屋租赁参考价格查询平台，安居客 | D18: 差饷物业估价署 (RVD) | E18: S&P Case-Shiller (via FRED)，Zillow

Sheet price-to-rent ratio
B1: 深圳 (Shenzhen) | H1: 香港 (Hong Kong) | I1: 旧金山湾区 (SF Bay Area)
B2: 博林天瑞 | C2: 新天鹅堡 | D2: 万科云城 | E2: 前海花园 | F2: 侨香公馆 | G2: 平均
A3: 当前房价 | B3: 90930 | C3: 229213 | D3: 50393 | E3: 59090 | F3: 42046 | H3: 182317 | I3: 1369171
A4: 居室月租金 | B4: 8641 | C4: 33800 | D4: 9543 | E4: 7673 | F4: 13033
A5: 居室面积 | B5: 85 | C5: 132 | D5: 92 | E5: 90 | F5: 129
A6: 当前月租金 | B6: =B4/B5 -> 101.65882 | C6: =C4/C5 -> 256.06061 | D6: =D4/D5 -> 103.72826 | E6: =E4/E5 -> 85.255556 | F6: =F4/F5 -> 101.03101 | H6: 421 | I6: 4000
A7: 租售比 | B7: =B6*12/B3 -> 0.013415879 | C7: =C6*12/C3 -> 0.013405554 | D7: =D6*12/D3 -> 0.024700636 | E7: =E6*12/E3 -> 0.017313702 | F7: =F6*12/F3 -> 0.028834422 | G7: =(SUM(B7:F7))/5 -> 0.019534039 | H7: =H6*12/H3 -> 0.027709978 | I7: =I6*12/I3 -> 0.03505771
A8: 居室数量 | B8: 2 | C8: 2 | D8: 3 | E8: 3 | F8: 3
A9: note：居室数、居室面积固定，都按照顶部的“X居室均价”计算，找到对应居室均价即可，可以统一口径、简化工作

Sheet Processed_HousePriceIndex_CN_SZ
A1: Date | B1: Value | C1: Region | D1: Type | E1: ReleaseDate(ObservationDate) | F1: 索引 | G1: Price_Prev_Month | H1: Price_Prev_Year | I1: MoM | J1: YoY | K1: 上月=100 | L1: 上年同月=100 | M1: 2020平均值 = 100 | N1: YTD(%)
A2: =rawData_HousePriceIndex_SZ!A2 -> 43831 | B2: =rawData_HousePriceIndex_SZ!B2 -> 54914 | C2: CN_SZ | D2: HousePriceIndex | E2: 43831 | F2: 0 | M2: {=ROUND( Processed_CN_SZ[[#This Row],[Value]] / AVERAGE( _xlfn._xlws.FILTER(Processed_CN_SZ[Value], YEAR(Processed_CN_SZ[Date])=2020) ), 3) * 100} -> 98.3 | N2: {=Processed_CN_SZ[[#This Row],[Value]] / _xlfn.XLOOKUP(MIN(_xlfn._xlws.FILTER(Processed_CN_SZ[Date], YEAR(Processed_CN_SZ[Date])=YEAR(Processed_CN_SZ[[#This Row],[Date]]))), Processed_CN_SZ[Date], Processed_CN_SZ[Value]) - 1} -> 0
A3: =rawData_HousePriceIndex_SZ!A3 -> 43862 | B3: =rawData_HousePriceIndex_SZ!B3 -> 55088 | C3: CN_SZ | D3: HousePriceIndex | E3: 45292 | F3: 1 | G3: 54914 | I3: =(B3-B2)/B2 -> 0.0031685909 | K3: =Processed_CN_SZ[[#This Row],[Value]]/B2 * 100 -> 100.31686 | M3: {=ROUND( Processed_CN_SZ[[#This Row],[Value]] / AVERAGE( _xlfn._xlws.FILTER(Processed_CN_SZ[Value], YEAR(Processed_CN_SZ[Date])=2020) ), 3) * 100} -> 98.6 | N3: {=Processed_CN_SZ[[#This Row],[Value]] / _xlfn.XLOOKUP(MIN(_xlfn._xlws.FILTER(Processed_CN_SZ[Date], YEAR(Processed_CN_SZ[Date])=YEAR(Processed_CN_SZ[[#This Row],[Date]]))), Processed_CN_SZ[Date], Processed_CN_SZ[Value]) - 1} -> 0.0031685909
A4: =rawData_HousePriceIndex_SZ!A4 -> 43891 | B4: =rawData_HousePriceIndex_SZ!B4 -> 55251 | C4: CN_SZ | D4: HousePriceIndex | E4: 45323 | F4: 2 | G4: 63948 | I4: =(B4-B3)/B3 -> 0.0029589021 | K4: =Processed_CN_SZ[[#This Row],[Value]]/B3 * 100 -> 100.29589 | M4: {=ROUND( Processed_CN_SZ[[#This Row],[Value]] / AVERAGE( _xlfn._xlws.FILTER(Processed_CN_SZ[Value], YEAR(Processed_CN_SZ[Date])=2020) ), 3) * 100} -> 98.9 | N4: {=Processed_CN_SZ[[#This Row],[Value]] / _xlfn.XLOOKUP(MIN(_xlfn._xlws.FILTER(Processed_CN_SZ[Date], YEAR(Processed_CN_SZ[Date])=YEAR(Processed_CN_SZ[[#This Row],[Date]]))), Processed_CN_SZ[Date], Processed_CN_SZ[Value]) - 1} -> 0.0061368686
A5: =rawData_HousePriceIndex_SZ!A5 -> 43922 | B5: =rawData_HousePriceIndex_SZ!B5 -> 55396 | C5: CN_SZ | D5: HousePriceIndex | E5: 45352 | F5: 3 | G5: 65093 | I5: =(B5-B4)/B4 -> 0.0026243869 | K5: =Processed_CN_SZ[[#This Row],[Value]]/B4 * 100 -> 100.26244 | M5: {=ROUND( Processed_CN_SZ[[#This Row],[Value]] / AVERAGE( _xlfn._xlws.FILTER(Processed_CN_SZ[Value], YEAR(Processed_CN_SZ[Date])=2020) ), 3) * 100} -> 99.2 | N5: {=Processed_CN_SZ[[#This Row],[Value]] / _xlfn.XLOOKUP(MIN(_xlfn._xlws.FILTER(Processed_CN_SZ[Date], YEAR(Processed_CN_SZ[Date])=YEAR(Processed_CN_SZ[[#This Row],[Date]]))), Processed_CN_SZ[Date], Processed_CN_SZ[Value]) - 1} -> 0.008777361
A6: =rawData_HousePriceIndex_SZ!A6 -> 43952 | B6: =rawData_HousePriceIndex_SZ!B6 -> 55545 | C6: CN_SZ | D6: HousePriceIndex | E6: 45383 | F6: 4 | G6: 63948 | I6: =(B6-B5)/B5 -> 0.0026897249 | K6: =Processed_CN_SZ[[#This Row],[Value]]/B5 * 100 -> 100.26897 | M6: {=ROUND( Processed_CN_SZ[[#This Row],[Value]] / AVERAGE( _xlfn._xlws.FILTER(Processed_CN_SZ[Value], YEAR(Processed_CN_SZ[Date])=2020) ), 3) * 100} -> 99.5 | N6: {=Processed_CN_SZ[[#This Row],[Value]] / _xlfn.XLOOKUP(MIN(_xlfn._xlws.FILTER(Processed_CN_SZ[Date], YEAR(Processed_CN_SZ[Date])=YEAR(Processed_CN_SZ[[#This Row],[Date]]))), Processed_CN_SZ[Date], Processed_CN_SZ[Value]) - 1} -> 0.011490695
A7: =rawData_HousePriceIndex_SZ!A7 -> 43983 | B7: =rawData_HousePriceIndex_SZ!B7 -> 55733 | C7: CN_SZ | D7: HousePriceIndex | E7: 45413 | F7: 5 | G7: 63001 | I7: =(B7-B6)/B6 -> 0.0033846431 | K7: =Processed_CN_SZ[[#This Row],[Value]]/B6 * 100 -> 100.33846 | M7: {=ROUND( Processed_CN_SZ[[#This Row],[Value]] / AVERAGE( _xlfn._xlws.FILTER(Processed_CN_SZ[Value], YEAR(Processed_CN_SZ[Date])=2020) ), 3) * 100} -> 99.8 | N7: {=Processed_CN_SZ[[#This Row],[Value]] / _xlfn.XLOOKUP(MIN(_xlfn._xlws.FILTER(Processed_CN_SZ[Date], YEAR(Processed_CN_SZ[Date])=YEAR(Processed_CN_SZ[[#This Row],[Date]]))), Processed_CN_SZ[Date], Processed_CN_SZ[Value]) - 1} -> 0.01491423
A8: =rawData_HousePriceIndex_SZ!A8 -> 44013 | B8: =rawData_HousePriceIndex_SZ!B8 -> 56033 | C8: CN_SZ | D8: HousePriceIndex | E8: 45444 | F8: 6 | G8: 62221 | I8: =(B8-B7)/B7 -> 0.0053828073 | K8: =Processed_CN_SZ[[#This Row],[Value]]/B7 * 100 -> 100.53828 | M8: {=ROUND( Processed_CN_SZ[[#This Row],[Value]] / AVERAGE( _xlfn._xlws.FILTER(Processed_CN_SZ[Value], YEAR(Processed_CN_SZ[Date])=2020) ), 3) * 100} -> 100.3 | N8: {=Processed_CN_SZ[[#This Row],[Value]] / _xlfn.XLOOKUP(MIN(_xlfn._xlws.FILTER(Processed_CN_SZ[Date], YEAR(Processed_CN_SZ[Date])=YEAR(Processed_CN_SZ[[#This Row],[Date]]))), Processed_CN_SZ[Date], Processed_CN_SZ[Value]) - 1} -> 0.020377317
A9: =rawData_HousePriceIndex_SZ!A9 -> 44044 | B9: =rawData_HousePriceIndex_SZ!B9 -> 56142 | C9: CN_SZ | D9: HousePriceIndex | E9: 45474 | F9: 7 | G9: 62093 | I9: =(B9-B8)/B8 -> 0.0019452822 | K9: =Processed_CN_SZ[[#This Row],[Value]]/B8 * 100 -> 100.19453 | M9: {=ROUND( Processed_CN_SZ[[#This Row],[Value]] / AVERAGE( _xlfn._xlws.FILTER(Processed_CN_SZ[Value], YEAR(Processed_CN_SZ[Date])=2020) ), 3) * 100} -> 100.5 | N9: {=Processed_CN_SZ[[#This Row],[Value]] / _xlfn.XLOOKUP(MIN(_xlfn._xlws.FILTER(Processed_CN_SZ[Date], YEAR(Processed_CN_SZ[Date])=YEAR(Processed_CN_SZ[[#This Row],[Date]]))), Processed_CN_SZ[Date], Processed_CN_SZ[Value]) - 1} -> 0.022362239
A10: =rawData_HousePriceIndex_SZ!A10 -> 44075 | B10: =rawData_HousePriceIndex_SZ!B10 -> 56286 | C10: CN_SZ | D10: HousePriceIndex | E10: 45505 | F10: 8 | G10: 61715 | I10: =(B10-B9)/B9 -> 0.0025649247 | K10: =Processed_CN_SZ[[#This Row],[Value]]/B9 * 100 -> 100.25649 | M10: {=ROUND( Processed_CN_SZ[[#This Row],[Value]] / AVERAGE( _xlfn._xlws.FILTER(Processed_CN_SZ[Value], YEAR(Processed_CN_SZ[Date])=2020) ), 3) * 100} -> 100.8 | N10: {=Processed_CN_SZ[[#This Row],[Value]] / _xlfn.XLOOKUP(MIN(_xlfn._xlws.FILTER(Processed_CN_SZ[Date], YEAR(Processed_CN_SZ[Date])=YEAR(Processed_CN_SZ[[#This Row],[Date]]))), Processed_CN_SZ[Date], Processed_CN_SZ[Value]) - 1} -> 0.024984521
A11: =rawData_HousePriceIndex_SZ!A11 -> 44105 | B11: =rawData_HousePriceIndex_SZ!B11 -> 56443 | C11: CN_SZ | D11: HousePriceIndex | E11: 45536 | F11: 9 | G11: 61323 | I11: =(B11-B10)/B10 -> 0.0027893259 | K11: =Processed_CN_SZ[[#This Row],[Value]]/B10 * 100 -> 100.27893 | M11: {=ROUND( Processed_CN_SZ[[#This Row],[Value]] / AVERAGE( _xlfn._xlws.FILTER(Processed_CN_SZ[Value], YEAR(Processed_CN_SZ[Date])=2020) ), 3) * 100} -> 101.1 | N11: {=Processed_CN_SZ[[#This Row],[Value]] / _xlfn.XLOOKUP(MIN(_xlfn._xlws.FILTER(Processed_CN_SZ[Date], YEAR(Processed_CN_SZ[Date])=YEAR(Processed_CN_SZ[[#This Row],[Date]]))), Processed_CN_SZ[Date], Processed_CN_SZ[Value]) - 1} -> 0.027843537
A12: =rawData_HousePriceIndex_SZ!A12 -> 44136 | B12: =rawData_HousePriceIndex_SZ!B12 -> 56600 | C12: CN_SZ | D12: HousePriceIndex | E12: 45566 | F12: 10 | G12: 59852 | I12: =(B12-B11)/B11 -> 0.0027815672 | K12: =Processed_CN_SZ[[#This Row],[Value]]/B11 * 100 -> 100.27816 | M12: {=ROUND( Processed_CN_SZ[[#This Row],[Value]] / AVERAGE( _xlfn._xlws.FILTER(Processed_CN_SZ[Value], YEAR(Processed_CN_SZ[Date])=2020) ), 3) * 100} -> 101.3 | N12: {=Processed_CN_SZ[[#This Row],[Value]] / _xlfn.XLOOKUP(MIN(_xlfn._xlws.FILTER(Processed_CN_SZ[Date], YEAR(Processed_CN_SZ[Date])=YEAR(Processed_CN_SZ[[#This Row],[Date]]))), Processed_CN_SZ[Date], Processed_CN_SZ[Value]) - 1} -> 0.030702553
A13: =rawData_HousePriceIndex_SZ!A13 -> 44166 | B13: =rawData_HousePriceIndex_SZ!B13 -> 56795 | C13: CN_SZ | D13: HousePriceIndex | E13: 45597 | F13: 11 | G13: 59148 | I13: =(B13-B12)/B12 -> 0.0034452297 | K13: =Processed_CN_SZ[[#This Row],[Value]]/B12 * 100 -> 100.34452 | M13: {=ROUND( Processed_CN_SZ[[#This Row],[Value]] / AVERAGE( _xlfn._xlws.FILTER(Processed_CN_SZ[Value], YEAR(Processed_CN_SZ[Date])=2020) ), 3) * 100} -> 101.7 | N13: {=Processed_CN_SZ[[#This Row],[Value]] / _xlfn.XLOOKUP(MIN(_xlfn._xlws.FILTER(Processed_CN_SZ[Date], YEAR(Processed_CN_SZ[Date])=YEAR(Processed_CN_SZ[[#This Row],[Date]]))), Processed_CN_SZ[Date], Processed_CN_SZ[Value]) - 1} -> 0.03425356
A14: =rawData_HousePriceIndex_SZ!A14 -> 44197 | B14: =rawData_HousePriceIndex_SZ!B14 -> 56967 | C14: CN_SZ | D14: HousePriceIndex | E14: 45627 | F14: 12 | G14: 58256 | H14: 54914 | I14: =(B14-B13)/B13 -> 0.0030284356 | J14: =(Processed_CN_SZ[[#This Row],[Value]]-B2)/B2 -> 0.03738573 | K14: =Processed_CN_SZ[[#This Row],[Value]]/B13 * 100 -> 100.30284 | L14: =Processed_CN_SZ[[#This Row],[Value]]/B2 * 100 -> 103.73857 | M14: {=ROUND( Processed_CN_SZ[[#This Row],[Value]] / AVERAGE( _xlfn._xlws.FILTER(Processed_CN_SZ[Value], YEAR(Processed_CN_SZ[Date])=2020) ), 3) * 100} -> 102 | N14: {=Processed_CN_SZ[[#This Row],[Value]] / _xlfn.XLOOKUP(MIN(_xlfn._xlws.FILTER(Processed_CN_SZ[Date], YEAR(Processed_CN_SZ[Date])=YEAR(Processed_CN_SZ[[#This Row],[Date]]))), Processed_CN_SZ[Date], Processed_CN_SZ[Value]) - 1} -> 0
A15: =rawData_HousePriceIndex_SZ!A15 -> 44228 | B15: =rawData_HousePriceIndex_SZ!B15 -> 57191 | C15: CN_SZ | D15: HousePriceIndex | E15: 45658 | F15: 13 | G15: 58499 | H15: 63948 | I15: =(B15-B14)/B14 -> 0.003932101 | J15: =(Processed_CN_SZ[[#This Row],[Value]]-B3)/B3 -> 0.038175283 | K15: =Processed_CN_SZ[[#This Row],[Value]]/B14 * 100 -> 100.39321 | L15: =Processed_CN_SZ[[#This Row],[Value]]/B3 * 100 -> 103.81753 | M15: {=ROUND( Processed_CN_SZ[[#This Row],[Value]] / AVERAGE( _xlfn._xlws.FILTER(Processed_CN_SZ[Value], YEAR(Processed_CN_SZ[Date])=2020) ), 3) * 100} -> 102.4 | N15: {=Processed_CN_SZ[[#This Row],[Value]] / _xlfn.XLOOKUP(MIN(_xlfn._xlws.FILTER(Processed_CN_SZ[Date], YEAR(Processed_CN_SZ[Date])=YEAR(Processed_CN_SZ[[#This Row],[Date]]))), Processed_CN_SZ[Date], Processed_CN_SZ[Value]) - 1} -> 0.003932101
A16: =rawData_HousePriceIndex_SZ!A16 -> 44256 | B16: =rawData_HousePriceIndex_SZ!B16 -> 57293 | C16: CN_SZ | D16: HousePriceIndex | E16: 45689 | F16: 14 | G16: 58518 | H16: 65093 | I16: =(B16-B15)/B15 -> 0.0017834974 | J16: =(Processed_CN_SZ[[#This Row],[Value]]-B4)/B4 -> 0.036958607 | K16: =Processed_CN_SZ[[#This Row],[Value]]/B15 * 100 -> 100.17835 | L16: =Processed_CN_SZ[[#This Row],[Value]]/B4 * 100 -> 103.69586 | M16: {=ROUND( Processed_CN_SZ[[#This Row],[Value]] / AVERAGE( _xlfn._xlws.FILTER(Processed_CN_SZ[Value], YEAR(Processed_CN_SZ[Date])=2020) ), 3) * 100} -> 102.6 | N16: {=Processed_CN_SZ[[#This Row],[Value]] / _xlfn.XLOOKUP(MIN(_xlfn._xlws.FILTER(Processed_CN_SZ[Date], YEAR(Processed_CN_SZ[Date])=YEAR(Processed_CN_SZ[[#This Row],[Date]]))), Processed_CN_SZ[Date], Processed_CN_SZ[Value]) - 1} -> 0.0057226113
A17: =rawData_HousePriceIndex_SZ!A17 -> 44287 | B17: =rawData_HousePriceIndex_SZ!B17 -> 57062 | C17: CN_SZ | D17: HousePriceIndex | E17: 45717 | F17: 15 | G17: 59245 | H17: 63948 | I17: =(B17-B16)/B16 -> -0.0040319062 | J17: =(Processed_CN_SZ[[#This Row],[Value]]-B5)/B5 -> 0.030074374 | K17: =Processed_CN_SZ[[#This Row],[Value]]/B16 * 100 -> 99.596809 | L17: =Processed_CN_SZ[[#This Row],[Value]]/B5 * 100 -> 103.00744 | M17: {=ROUND( Processed_CN_SZ[[#This Row],[Value]] / AVERAGE( _xlfn._xlws.FILTER(Processed_CN_SZ[Value], YEAR(Processed_CN_SZ[Date])=2020) ), 3) * 100} -> 102.2 | N17: {=Processed_CN_SZ[[#This Row],[Value]] / _xlfn.XLOOKUP(MIN(_xlfn._xlws.FILTER(Processed_CN_SZ[Date], YEAR(Processed_CN_SZ[Date])=YEAR(Processed_CN_SZ[[#This Row],[Date]]))), Processed_CN_SZ[Date], Processed_CN_SZ[Value]) - 1} -> 0.0016676321
A18: =rawData_HousePriceIndex_SZ!A18 -> 44317 | B18: =rawData_HousePriceIndex_SZ!B18 -> 56928 | C18: CN_SZ | D18: HousePriceIndex | E18: 45748 | F18: 16 | G18: 58586 | H18: 63001 | I18: =(B18-B17)/B17 -> -0.0023483229 | J18: =(Processed_CN_SZ[[#This Row],[Value]]-B6)/B6 -> 0.024898731 | K18: =Processed_CN_SZ[[#This Row],[Value]]/B17 * 100 -> 99.765168 | L18: =Processed_CN_SZ[[#This Row],[Value]]/B6 * 100 -> 102.48987 | M18: {=ROUND( Processed_CN_SZ[[#This Row],[Value]] / AVERAGE( _xlfn._xlws.FILTER(Processed_CN_SZ[Value], YEAR(Processed_CN_SZ[Date])=2020) ), 3) * 100} -> 101.9 | N18: {=Processed_CN_SZ[[#This Row],[Value]] / _xlfn.XLOOKUP(MIN(_xlfn._xlws.FILTER(Processed_CN_SZ[Date], YEAR(Processed_CN_SZ[Date])=YEAR(Processed_CN_SZ[[#This Row],[Date]]))), Processed_CN_SZ[Date], Processed_CN_SZ[Value]) - 1} -> -0.00068460688
A19: =rawData_HousePriceIndex_SZ!A19 -> 44348 | B19: =rawData_HousePriceIndex_SZ!B19 -> 56919 | C19: CN_SZ | D19: HousePriceIndex | E19: 45778 | F19: 17 | G19: 57856 | H19: 62221 | I19: =(B19-B18)/B18 -> -0.00015809444 | J19: =(Processed_CN_SZ[[#This Row],[Value]]-B7)/B7 -> 0.021280032 | K19: =Processed_CN_SZ[[#This Row],[Value]]/B18 * 100 -> 99.984191 | L19: =Processed_CN_SZ[[#This Row],[Value]]/B7 * 100 -> 102.128 | M19: {=ROUND( Processed_CN_SZ[[#This Row],[Value]] / AVERAGE( _xlfn._xlws.FILTER(Processed_CN_SZ[Value], YEAR(Processed_CN_SZ[Date])=2020) ), 3) * 100} -> 101.9 | N19: {=Processed_CN_SZ[[#This Row],[Value]] / _xlfn.XLOOKUP(MIN(_xlfn._xlws.FILTER(Processed_CN_SZ[Date], YEAR(Processed_CN_SZ[Date])=YEAR(Processed_CN_SZ[[#This Row],[Date]]))), Processed_CN_SZ[Date], Processed_CN_SZ[Value]) - 1} -> -0.00084259308
A20: =rawData_HousePriceIndex_SZ!A20 -> 44378 | B20: =rawData_HousePriceIndex_SZ!B20 -> 57484 | C20: CN_SZ | D20: HousePriceIndex | E20: 45809 | F20: 18 | G20: 57823 | H20: 62093 | I20: =(B20-B19)/B19 -> 0.0099263866 | J20: =(Processed_CN_SZ[[#This Row],[Value]]-B8)/B8 -> 0.025895454 | K20: =Processed_CN_SZ[[#This Row],[Value]]/B19 * 100 -> 100.99264 | L20: =Processed_CN_SZ[[#This Row],[Value]]/B8 * 100 -> 102.58955 | M20: {=ROUND( Processed_CN_SZ[[#This Row],[Value]] / AVERAGE( _xlfn._xlws.FILTER(Processed_CN_SZ[Value], YEAR(Processed_CN_SZ[Date])=2020) ), 3) * 100} -> 102.9 | N20: {=Processed_CN_SZ[[#This Row],[Value]] / _xlfn.XLOOKUP(MIN(_xlfn._xlws.FILTER(Processed_CN_SZ[Date], YEAR(Processed_CN_SZ[Date])=YEAR(Processed_CN_SZ[[#This Row],[Date]]))), Processed_CN_SZ[Date], Processed_CN_SZ[Value]) - 1} -> 0.0090754296
A21: =rawData_HousePriceIndex_SZ!A21 -> 44409 | B21: =rawData_HousePriceIndex_SZ!B21 -> 57218 | C21: CN_SZ | D21: HousePriceIndex | E21: 45839 | F21: 19 | G21: 56960 | H21: 61715 | I21: =(B21-B20)/B20 -> -0.0046273746 | J21: =(Processed_CN_SZ[[#This Row],[Value]]-B9)/B9 -> 0.019165687 | K21: =Processed_CN_SZ[[#This Row],[Value]]/B20 * 100 -> 99.537263 | L21: =Processed_CN_SZ[[#This Row],[Value]]/B9 * 100 -> 101.91657 | M21: {=ROUND( Processed_CN_SZ[[#This Row],[Value]] / AVERAGE( _xlfn._xlws.FILTER(Processed_CN_SZ[Value], YEAR(Processed_CN_SZ[Date])=2020) ), 3) * 100} -> 102.4 | N21: {=Processed_CN_SZ[[#This Row],[Value]] / _xlfn.XLOOKUP(MIN(_xlfn._xlws.FILTER(Processed_CN_SZ[Date], YEAR(Processed_CN_SZ[Date])=YEAR(Processed_CN_SZ[[#This Row],[Date]]))), Processed_CN_SZ[Date], Processed_CN_SZ[Value]) - 1} -> 0.0044060596
A22: =rawData_HousePriceIndex_SZ!A22 -> 44440 | B22: =rawData_HousePriceIndex_SZ!B22 -> 57086 | C22: CN_SZ | D22: HousePriceIndex | E22: 45870 | F22: 20 | G22: 55836 | H22: 61323 | I22: =(B22-B21)/B21 -> -0.0023069663 | J22: =(Processed_CN_SZ[[#This Row],[Value]]-B10)/B10 -> 0.014213126 | K22: =Processed_CN_SZ[[#This Row],[Value]]/B21 * 100 -> 99.769303 | L22: =Processed_CN_SZ[[#This Row],[Value]]/B10 * 100 -> 101.42131 | M22: {=ROUND( Processed_CN_SZ[[#This Row],[Value]] / AVERAGE( _xlfn._xlws.FILTER(Processed_CN_SZ[Value], YEAR(Processed_CN_SZ[Date])=2020) ), 3) * 100} -> 102.2 | N22: {=Processed_CN_SZ[[#This Row],[Value]] / _xlfn.XLOOKUP(MIN(_xlfn._xlws.FILTER(Processed_CN_SZ[Date], YEAR(Processed_CN_SZ[Date])=YEAR(Processed_CN_SZ[[#This Row],[Date]]))), Processed_CN_SZ[Date], Processed_CN_SZ[Value]) - 1} -> 0.0020889287
A23: =rawData_HousePriceIndex_SZ!A23 -> 44470 | B23: =rawData_HousePriceIndex_SZ!B23 -> 56539 | C23: CN_SZ | D23: HousePriceIndex | E23: 45901 | F23: 21 | G23: 55407 | H23: 59852 | I23: =(B23-B22)/B22 -> -0.0095820341 | J23: =(Processed_CN_SZ[[#This Row],[Value]]-B11)/B11 -> 0.0017008309 | K23: =Processed_CN_SZ[[#This Row],[Value]]/B22 * 100 -> 99.041797 | L23: =Processed_CN_SZ[[#This Row],[Value]]/B11 * 100 -> 100.17008 | M23: {=ROUND( Processed_CN_SZ[[#This Row],[Value]] / AVERAGE( _xlfn._xlws.FILTER(Processed_CN_SZ[Value], YEAR(Processed_CN_SZ[Date])=2020) ), 3) * 100} -> 101.2 | N23: {=Processed_CN_SZ[[#This Row],[Value]] / _xlfn.XLOOKUP(MIN(_xlfn._xlws.FILTER(Processed_CN_SZ[Date], YEAR(Processed_CN_SZ[Date])=YEAR(Processed_CN_SZ[[#This Row],[Date]]))), Processed_CN_SZ[Date], Processed_CN_SZ[Value]) - 1} -> -0.0075131216
A24: =rawData_HousePriceIndex_SZ!A24 -> 44501 | B24: =rawData_HousePriceIndex_SZ!B24 -> 56913 | C24: CN_SZ | D24: HousePriceIndex | E24: 45931 | F24: 22 | G24: 54812 | H24: 59148 | I24: =(B24-B23)/B23 -> 0.006614903 | J24: =(Processed_CN_SZ[[#This Row],[Value]]-B12)/B12 -> 0.0055300353 | K24: =Processed_CN_SZ[[#This Row],[Value]]/B23 * 100 -> 100.66149 | L24: =Processed_CN_SZ[[#This Row],[Value]]/B12 * 100 -> 100.553 | M24: {=ROUND( Processed_CN_SZ[[#This Row],[Value]] / AVERAGE( _xlfn._xlws.FILTER(Processed_CN_SZ[Value], YEAR(Processed_CN_SZ[Date])=2020) ), 3) * 100} -> 101.9 | N24: {=Processed_CN_SZ[[#This Row],[Value]] / _xlfn.XLOOKUP(MIN(_xlfn._xlws.FILTER(Processed_CN_SZ[Date], YEAR(Processed_CN_SZ[Date])=YEAR(Processed_CN_SZ[[#This Row],[Date]]))), Processed_CN_SZ[Date], Processed_CN_SZ[Value]) - 1} -> -0.00094791722
A25: =rawData_HousePriceIndex_SZ!A25 -> 44531 | B25: =rawData_HousePriceIndex_SZ!B25 -> 57083 | I25: =(B25-B24)/B24 -> 0.0029870153 | J25: =(Processed_CN_SZ[[#This Row],[Value]]-B13)/B13 -> 0.0050708689 | K25: =Processed_CN_SZ[[#This Row],[Value]]/B24 * 100 -> 100.2987 | L25: =Processed_CN_SZ[[#This Row],[Value]]/B13 * 100 -> 100.50709 | M25: {=ROUND( Processed_CN_SZ[[#This Row],[Value]] / AVERAGE( _xlfn._xlws.FILTER(Processed_CN_SZ[Value], YEAR(Processed_CN_SZ[Date])=2020) ), 3) * 100} -> 102.2 | N25: {=Processed_CN_SZ[[#This Row],[Value]] / _xlfn.XLOOKUP(MIN(_xlfn._xlws.FILTER(Processed_CN_SZ[Date], YEAR(Processed_CN_SZ[Date])=YEAR(Processed_CN_SZ[[#This Row],[Date]]))), Processed_CN_SZ[Date], Processed_CN_SZ[Value]) - 1} -> 0.0020362666
A26: =rawData_HousePriceIndex_SZ!A26 -> 44562 | B26: =rawData_HousePriceIndex_SZ!B26 -> 57198 | I26: =(B26-B25)/B25 -> 0.0020146103 | J26: =(Processed_CN_SZ[[#This Row],[Value]]-B14)/B14 -> 0.0040549792 | K26: =Processed_CN_SZ[[#This Row],[Value]]/B25 * 100 -> 100.20146 | L26: =Processed_CN_SZ[[#This Row],[Value]]/B14 * 100 -> 100.4055 | M26: {=ROUND( Processed_CN_SZ[[#This Row],[Value]] / AVERAGE( _xlfn._xlws.FILTER(Processed_CN_SZ[Value], YEAR(Processed_CN_SZ[Date])=2020) ), 3) * 100} -> 102.4 | N26: {=Processed_CN_SZ[[#This Row],[Value]] / _xlfn.XLOOKUP(MIN(_xlfn._xlws.FILTER(Processed_CN_SZ[Date], YEAR(Processed_CN_SZ[Date])=YEAR(Processed_CN_SZ[[#This Row],[Date]]))), Processed_CN_SZ[Date], Processed_CN_SZ[Value]) - 1} -> 0
A27: =rawData_HousePriceIndex_SZ!A27 -> 44593 | B27: =rawData_HousePriceIndex_SZ!B27 -> 57376 | I27: =(B27-B26)/B26 -> 0.0031119969 | J27: =(Processed_CN_SZ[[#This Row],[Value]]-B15)/B15 -> 0.0032347747 | K27: =Processed_CN_SZ[[#This Row],[Value]]/B26 * 100 -> 100.3112 | L27: =Processed_CN_SZ[[#This Row],[Value]]/B15 * 100 -> 100.32348 | M27: {=ROUND( Processed_CN_SZ[[#This Row],[Value]] / AVERAGE( _xlfn._xlws.FILTER(Processed_CN_SZ[Value], YEAR(Processed_CN_SZ[Date])=2020) ), 3) * 100} -> 102.7 | N27: {=Processed_CN_SZ[[#This Row],[Value]] / _xlfn.XLOOKUP(MIN(_xlfn._xlws.FILTER(Processed_CN_SZ[Date], YEAR(Processed_CN_SZ[Date])=YEAR(Processed_CN_SZ[[#This Row],[Date]]))), Processed_CN_SZ[Date], Processed_CN_SZ[Value]) - 1} -> 0.0031119969
A28: =rawData_HousePriceIndex_SZ!A28 -> 44621 | B28: =rawData_HousePriceIndex_SZ!B28 -> 57510 | I28: =(B28-B27)/B27 -> 0.0023354713 | J28: =(Processed_CN_SZ[[#This Row],[Value]]-B16)/B16 -> 0.0037875482 | K28: =Processed_CN_SZ[[#This Row],[Value]]/B27 * 100 -> 100.23355 | L28: =Processed_CN_SZ[[#This Row],[Value]]/B16 * 100 -> 100.37875 | M28: {=ROUND( Processed_CN_SZ[[#This Row],[Value]] / AVERAGE( _xlfn._xlws.FILTER(Processed_CN_SZ[Value], YEAR(Processed_CN_SZ[Date])=2020) ), 3) * 100} -> 103 | N28: {=Processed_CN_SZ[[#This Row],[Value]] / _xlfn.XLOOKUP(MIN(_xlfn._xlws.FILTER(Processed_CN_SZ[Date], YEAR(Processed_CN_SZ[Date])=YEAR(Processed_CN_SZ[[#This Row],[Date]]))), Processed_CN_SZ[Date], Processed_CN_SZ[Value]) - 1} -> 0.0054547362
A29: =rawData_HousePriceIndex_SZ!A29 -> 44652 | B29: =rawData_HousePriceIndex_SZ!B29 -> 57640 | I29: =(B29-B28)/B28 -> 0.0022604764 | J29: =(Processed_CN_SZ[[#This Row],[Value]]-B17)/B17 -> 0.010129333 | K29: =Processed_CN_SZ[[#This Row],[Value]]/B28 * 100 -> 100.22605 | L29: =Processed_CN_SZ[[#This Row],[Value]]/B17 * 100 -> 101.01293 | M29: {=ROUND( Processed_CN_SZ[[#This Row],[Value]] / AVERAGE( _xlfn._xlws.FILTER(Processed_CN_SZ[Value], YEAR(Processed_CN_SZ[Date])=2020) ), 3) * 100} -> 103.2 | N29: {=Processed_CN_SZ[[#This Row],[Value]] / _xlfn.XLOOKUP(MIN(_xlfn._xlws.FILTER(Processed_CN_SZ[Date], YEAR(Processed_CN_SZ[Date])=YEAR(Processed_CN_SZ[[#This Row],[Date]]))), Processed_CN_SZ[Date], Processed_CN_SZ[Value]) - 1} -> 0.0077275429
A30: =rawData_HousePriceIndex_SZ!A30 -> 44682 | B30: =rawData_HousePriceIndex_SZ!B30 -> 57411 | I30: =(B30-B29)/B29 -> -0.0039729355 | J30: =(Processed_CN_SZ[[#This Row],[Value]]-B18)/B18 -> 0.0084844013 | K30: =Processed_CN_SZ[[#This Row],[Value]]/B29 * 100 -> 99.602706 | L30: =Processed_CN_SZ[[#This Row],[Value]]/B18 * 100 -> 100.84844 | M30: {=ROUND( Processed_CN_SZ[[#This Row],[Value]] / AVERAGE( _xlfn._xlws.FILTER(Processed_CN_SZ[Value], YEAR(Processed_CN_SZ[Date])=2020) ), 3) * 100} -> 102.8 | N30: {=Processed_CN_SZ[[#This Row],[Value]] / _xlfn.XLOOKUP(MIN(_xlfn._xlws.FILTER(Processed_CN_SZ[Date], YEAR(Processed_CN_SZ[Date])=YEAR(Processed_CN_SZ[[#This Row],[Date]]))), Processed_CN_SZ[Date], Processed_CN_SZ[Value]) - 1} -> 0.0037239064
A31: =rawData_HousePriceIndex_SZ!A31 -> 44713 | B31: =rawData_HousePriceIndex_SZ!B31 -> 56843 | I31: =(B31-B30)/B30 -> -0.0098935744 | J31: =(Processed_CN_SZ[[#This Row],[Value]]-B19)/B19 -> -0.0013352308 | K31: =Processed_CN_SZ[[#This Row],[Value]]/B30 * 100 -> 99.010643 | L31: =Processed_CN_SZ[[#This Row],[Value]]/B19 * 100 -> 99.866477 | M31: {=ROUND( Processed_CN_SZ[[#This Row],[Value]] / AVERAGE( _xlfn._xlws.FILTER(Processed_CN_SZ[Value], YEAR(Processed_CN_SZ[Date])=2020) ), 3) * 100} -> 101.8 | N31: {=Processed_CN_SZ[[#This Row],[Value]] / _xlfn.XLOOKUP(MIN(_xlfn._xlws.FILTER(Processed_CN_SZ[Date], YEAR(Processed_CN_SZ[Date])=YEAR(Processed_CN_SZ[[#This Row],[Date]]))), Processed_CN_SZ[Date], Processed_CN_SZ[Value]) - 1} -> -0.0062065107
A32: =rawData_HousePriceIndex_SZ!A32 -> 44743 | B32: =rawData_HousePriceIndex_SZ!B32 -> 56732 | I32: =(B32-B31)/B31 -> -0.001952747 | J32: =(Processed_CN_SZ[[#This Row],[Value]]-B20)/B20 -> -0.013081901 | K32: =Processed_CN_SZ[[#This Row],[Value]]/B31 * 100 -> 99.804725 | L32: =Processed_CN_SZ[[#This Row],[Value]]/B20 * 100 -> 98.69181 | M32: {=ROUND( Processed_CN_SZ[[#This Row],[Value]] / AVERAGE( _xlfn._xlws.FILTER(Processed_CN_SZ[Value], YEAR(Processed_CN_SZ[Date])=2020) ), 3) * 100} -> 101.6 | N32: {=Processed_CN_SZ[[#This Row],[Value]] / _xlfn.XLOOKUP(MIN(_xlfn._xlws.FILTER(Processed_CN_SZ[Date], YEAR(Processed_CN_SZ[Date])=YEAR(Processed_CN_SZ[[#This Row],[Date]]))), Processed_CN_SZ[Date], Processed_CN_SZ[Value]) - 1} -> -0.008147138
A33: =rawData_HousePriceIndex_SZ!A33 -> 44774 | B33: =rawData_HousePriceIndex_SZ!B33 -> 56841 | I33: =(B33-B32)/B32 -> 0.0019213142 | J33: =(Processed_CN_SZ[[#This Row],[Value]]-B21)/B21 -> -0.0065888357 | K33: =Processed_CN_SZ[[#This Row],[Value]]/B32 * 100 -> 100.19213 | L33: =Processed_CN_SZ[[#This Row],[Value]]/B21 * 100 -> 99.341116 | M33: {=ROUND( Processed_CN_SZ[[#This Row],[Value]] / AVERAGE( _xlfn._xlws.FILTER(Processed_CN_SZ[Value], YEAR(Processed_CN_SZ[Date])=2020) ), 3) * 100} -> 101.8 | N33: {=Processed_CN_SZ[[#This Row],[Value]] / _xlfn.XLOOKUP(MIN(_xlfn._xlws.FILTER(Processed_CN_SZ[Date], YEAR(Processed_CN_SZ[Date])=YEAR(Processed_CN_SZ[[#This Row],[Date]]))), Processed_CN_SZ[Date], Processed_CN_SZ[Value]) - 1} -> -0.006241477
A34: =rawData_HousePriceIndex_SZ!A34 -> 44805 | B34: =rawData_HousePriceIndex_SZ!B34 -> 57203 | I34: =(B34-B33)/B33 -> 0.0063686424 | J34: =(Processed_CN_SZ[[#This Row],[Value]]-B22)/B22 -> 0.0020495393 | K34: =Processed_CN_SZ[[#This Row],[Value]]/B33 * 100 -> 100.63686 | L34: =Processed_CN_SZ[[#This Row],[Value]]/B22 * 100 -> 100.20495 | M34: {=ROUND( Processed_CN_SZ[[#This Row],[Value]] / AVERAGE( _xlfn._xlws.FILTER(Processed_CN_SZ[Value], YEAR(Processed_CN_SZ[Date])=2020) ), 3) * 100} -> 102.4 | N34: {=Processed_CN_SZ[[#This Row],[Value]] / _xlfn.XLOOKUP(MIN(_xlfn._xlws.FILTER(Processed_CN_SZ[Date], YEAR(Processed_CN_SZ[Date])=YEAR(Processed_CN_SZ[[#This Row],[Date]]))), Processed_CN_SZ[Date], Processed_CN_SZ[Value]) - 1} -> 8.7415644e-05
A35: =rawData_HousePriceIndex_SZ!A35 -> 44835 | B35: =rawData_HousePriceIndex_SZ!B35 -> 57297 | I35: =(B35-B34)/B34 -> 0.0016432705 | J35: =(Processed_CN_SZ[[#This Row],[Value]]-B23)/B23 -> 0.013406675 | K35: =Processed_CN_SZ[[#This Row],[Value]]/B34 * 100 -> 100.16433 | L35: =Processed_CN_SZ[[#This Row],[Value]]/B23 * 100 -> 101.34067 | M35: {=ROUND( Processed_CN_SZ[[#This Row],[Value]] / AVERAGE( _xlfn._xlws.FILTER(Processed_CN_SZ[Value], YEAR(Processed_CN_SZ[Date])=2020) ), 3) * 100} -> 102.6 | N35: {=Processed_CN_SZ[[#This Row],[Value]] / _xlfn.XLOOKUP(MIN(_xlfn._xlws.FILTER(Processed_CN_SZ[Date], YEAR(Processed_CN_SZ[Date])=YEAR(Processed_CN_SZ[[#This Row],[Date]]))), Processed_CN_SZ[Date], Processed_CN_SZ[Value]) - 1} -> 0.0017308297
A36: =rawData_HousePriceIndex_SZ!A36 -> 44866 | B36: =rawData_HousePriceIndex_SZ!B36 -> 57456 | I36: =(B36-B35)/B35 -> 0.0027750144 | J36: =(Processed_CN_SZ[[#This Row],[Value]]-B24)/B24 -> 0.0095408782 | K36: =Processed_CN_SZ[[#This Row],[Value]]/B35 * 100 -> 100.2775 | L36: =Processed_CN_SZ[[#This Row],[Value]]/B24 * 100 -> 100.95409 | M36: {=ROUND( Processed_CN_SZ[[#This Row],[Value]] / AVERAGE( _xlfn._xlws.FILTER(Processed_CN_SZ[Value], YEAR(Processed_CN_SZ[Date])=2020) ), 3) * 100} -> 102.9 | N36: {=Processed_CN_SZ[[#This Row],[Value]] / _xlfn.XLOOKUP(MIN(_xlfn._xlws.FILTER(Processed_CN_SZ[Date], YEAR(Processed_CN_SZ[Date])=YEAR(Processed_CN_SZ[[#This Row],[Date]]))), Processed_CN_SZ[Date], Processed_CN_SZ[Value]) - 1} -> 0.0045106472
... A79: =rawData_HousePriceIndex_SZ!A79 -> 46174 | B79: =rawData_HousePriceIndex_SZ!B79 -> 52253 | I79: =(B79-B78)/B78 -> -0.0025388463 | J79: =(Processed_CN_SZ[[#This Row],[Value]]-B67)/B67 -> -0.082636938 | K79: =Processed_CN_SZ[[#This Row],[Value]]/B78 * 100 -> 99.746115 | L79: =Processed_CN_SZ[[#This Row],[Value]]/B67 * 100 -> 91.736306 | M79: {=ROUND( Processed_CN_SZ[[#This Row],[Value]] / AVERAGE( _xlfn._xlws.FILTER(Processed_CN_SZ[Value], YEAR(Processed_CN_SZ[Date])=2020) ), 3) * 100} -> 93.6 | N79: {=Processed_CN_SZ[[#This Row],[Value]] / _xlfn.XLOOKUP(MIN(_xlfn._xlws.FILTER(Processed_CN_SZ[Date], YEAR(Processed_CN_SZ[Date])=YEAR(Processed_CN_SZ[[#This Row],[Date]]))), Processed_CN_SZ[Date], Processed_CN_SZ[Value]) - 1} -> -0.021296123

Sheet Processed_HousePriceIndex_CN_HK
A1: Date | B1: Value | C1: Region | D1: Type | E1: ReleaseDate(ObservationDate) | F1: 索引 | G1: Price_Prev_Month | H1: Price_Prev_Year | I1: MoM | J1: YoY | K1: 上月=100 | L1: 上年同月=100 | M1: 2020平均值 = 100 | N1: YTD(%)
A2: =rawData_HousePriceIndex_HK!A2 -> 43831 | B2: =rawData_HousePriceIndex_HK!B2 -> 379.7 | C2: CN_HK | D2: HousePriceIndex | E2: 43831 | F2: 0 | M2: {=ROUND( Processed_CN_HK[[#This Row],[Value]] / AVERAGE( _xlfn._xlws.FILTER(Processed_CN_HK[Value], YEAR(Processed_CN_HK[Date])=2020) ), 3) * 100} -> 99.6 | N2: {=Processed_CN_HK[[#This Row],[Value]] / _xlfn.XLOOKUP(MIN(_xlfn._xlws.FILTER(Processed_CN_HK[Date], YEAR(Processed_CN_HK[Date])=YEAR(Processed_CN_HK[[#This Row],[Date]]))), Processed_CN_HK[Date], Processed_CN_HK[Value]) - 1} -> 0
A3: =rawData_HousePriceIndex_HK!A3 -> 43862 | B3: =rawData_HousePriceIndex_HK!B3 -> 373.4 | C3: CN_HK | D3: HousePriceIndex | E3: 43862 | F3: 1 | G3: 380 | I3: =(B3-B2)/B2 -> -0.016592046 | K3: =Processed_CN_HK[[#This Row],[Value]]/B2 * 100 -> 98.340795 | M3: {=ROUND( Processed_CN_HK[[#This Row],[Value]] / AVERAGE( _xlfn._xlws.FILTER(Processed_CN_HK[Value], YEAR(Processed_CN_HK[Date])=2020) ), 3) * 100} -> 98 | N3: {=Processed_CN_HK[[#This Row],[Value]] / _xlfn.XLOOKUP(MIN(_xlfn._xlws.FILTER(Processed_CN_HK[Date], YEAR(Processed_CN_HK[Date])=YEAR(Processed_CN_HK[[#This Row],[Date]]))), Processed_CN_HK[Date], Processed_CN_HK[Value]) - 1} -> -0.016592046
A4: =rawData_HousePriceIndex_HK!A4 -> 43891 | B4: =rawData_HousePriceIndex_HK!B4 -> 378.4 | C4: CN_HK | D4: HousePriceIndex | E4: 43891 | F4: 2 | G4: 373 | I4: =(B4-B3)/B3 -> 0.013390466 | K4: =Processed_CN_HK[[#This Row],[Value]]/B3 * 100 -> 101.33905 | M4: {=ROUND( Processed_CN_HK[[#This Row],[Value]] / AVERAGE( _xlfn._xlws.FILTER(Processed_CN_HK[Value], YEAR(Processed_CN_HK[Date])=2020) ), 3) * 100} -> 99.3 | N4: {=Processed_CN_HK[[#This Row],[Value]] / _xlfn.XLOOKUP(MIN(_xlfn._xlws.FILTER(Processed_CN_HK[Date], YEAR(Processed_CN_HK[Date])=YEAR(Processed_CN_HK[[#This Row],[Date]]))), Processed_CN_HK[Date], Processed_CN_HK[Value]) - 1} -> -0.0034237556
A5: =rawData_HousePriceIndex_HK!A5 -> 43922 | B5: =rawData_HousePriceIndex_HK!B5 -> 377.5 | C5: CN_HK | D5: HousePriceIndex | E5: 43922 | F5: 3 | G5: 378 | I5: =(B5-B4)/B4 -> -0.0023784355 | K5: =Processed_CN_HK[[#This Row],[Value]]/B4 * 100 -> 99.762156 | M5: {=ROUND( Processed_CN_HK[[#This Row],[Value]] / AVERAGE( _xlfn._xlws.FILTER(Processed_CN_HK[Value], YEAR(Processed_CN_HK[Date])=2020) ), 3) * 100} -> 99 | N5: {=Processed_CN_HK[[#This Row],[Value]] / _xlfn.XLOOKUP(MIN(_xlfn._xlws.FILTER(Processed_CN_HK[Date], YEAR(Processed_CN_HK[Date])=YEAR(Processed_CN_HK[[#This Row],[Date]]))), Processed_CN_HK[Date], Processed_CN_HK[Value]) - 1} -> -0.0057940479
A6: =rawData_HousePriceIndex_HK!A6 -> 43952 | B6: =rawData_HousePriceIndex_HK!B6 -> 386.1 | C6: CN_HK | D6: HousePriceIndex | E6: 43952 | F6: 4 | G6: 378 | I6: =(B6-B5)/B5 -> 0.022781457 | K6: =Processed_CN_HK[[#This Row],[Value]]/B5 * 100 -> 102.27815 | M6: {=ROUND( Processed_CN_HK[[#This Row],[Value]] / AVERAGE( _xlfn._xlws.FILTER(Processed_CN_HK[Value], YEAR(Processed_CN_HK[Date])=2020) ), 3) * 100} -> 101.3 | N6: {=Processed_CN_HK[[#This Row],[Value]] / _xlfn.XLOOKUP(MIN(_xlfn._xlws.FILTER(Processed_CN_HK[Date], YEAR(Processed_CN_HK[Date])=YEAR(Processed_CN_HK[[#This Row],[Date]]))), Processed_CN_HK[Date], Processed_CN_HK[Value]) - 1} -> 0.016855412
A7: =rawData_HousePriceIndex_HK!A7 -> 43983 | B7: =rawData_HousePriceIndex_HK!B7 -> 386.7 | C7: CN_HK | D7: HousePriceIndex | E7: 43983 | F7: 5 | G7: 386 | I7: =(B7-B6)/B6 -> 0.0015540016 | K7: =Processed_CN_HK[[#This Row],[Value]]/B6 * 100 -> 100.1554 | M7: {=ROUND( Processed_CN_HK[[#This Row],[Value]] / AVERAGE( _xlfn._xlws.FILTER(Processed_CN_HK[Value], YEAR(Processed_CN_HK[Date])=2020) ), 3) * 100} -> 101.4 | N7: {=Processed_CN_HK[[#This Row],[Value]] / _xlfn.XLOOKUP(MIN(_xlfn._xlws.FILTER(Processed_CN_HK[Date], YEAR(Processed_CN_HK[Date])=YEAR(Processed_CN_HK[[#This Row],[Date]]))), Processed_CN_HK[Date], Processed_CN_HK[Value]) - 1} -> 0.018435607
A8: =rawData_HousePriceIndex_HK!A8 -> 44013 | B8: =rawData_HousePriceIndex_HK!B8 -> 385.4 | C8: CN_HK | D8: HousePriceIndex | E8: 44013 | F8: 6 | G8: 387 | I8: =(B8-B7)/B7 -> -0.0033617792 | K8: =Processed_CN_HK[[#This Row],[Value]]/B7 * 100 -> 99.663822 | M8: {=ROUND( Processed_CN_HK[[#This Row],[Value]] / AVERAGE( _xlfn._xlws.FILTER(Processed_CN_HK[Value], YEAR(Processed_CN_HK[Date])=2020) ), 3) * 100} -> 101.1 | N8: {=Processed_CN_HK[[#This Row],[Value]] / _xlfn.XLOOKUP(MIN(_xlfn._xlws.FILTER(Processed_CN_HK[Date], YEAR(Processed_CN_HK[Date])=YEAR(Processed_CN_HK[[#This Row],[Date]]))), Processed_CN_HK[Date], Processed_CN_HK[Value]) - 1} -> 0.015011851
A9: =rawData_HousePriceIndex_HK!A9 -> 44044 | B9: =rawData_HousePriceIndex_HK!B9 -> 382 | C9: CN_HK | D9: HousePriceIndex | E9: 44044 | F9: 7 | G9: 385 | I9: =(B9-B8)/B8 -> -0.0088220031 | K9: =Processed_CN_HK[[#This Row],[Value]]/B8 * 100 -> 99.1178 | M9: {=ROUND( Processed_CN_HK[[#This Row],[Value]] / AVERAGE( _xlfn._xlws.FILTER(Processed_CN_HK[Value], YEAR(Processed_CN_HK[Date])=2020) ), 3) * 100} -> 100.2 | N9: {=Processed_CN_HK[[#This Row],[Value]] / _xlfn.XLOOKUP(MIN(_xlfn._xlws.FILTER(Processed_CN_HK[Date], YEAR(Processed_CN_HK[Date])=YEAR(Processed_CN_HK[[#This Row],[Date]]))), Processed_CN_HK[Date], Processed_CN_HK[Value]) - 1} -> 0.0060574137
A10: =rawData_HousePriceIndex_HK!A10 -> 44075 | B10: =rawData_HousePriceIndex_HK!B10 -> 383.1 | C10: CN_HK | D10: HousePriceIndex | E10: 44075 | F10: 8 | G10: 382 | I10: =(B10-B9)/B9 -> 0.0028795812 | K10: =Processed_CN_HK[[#This Row],[Value]]/B9 * 100 -> 100.28796 | M10: {=ROUND( Processed_CN_HK[[#This Row],[Value]] / AVERAGE( _xlfn._xlws.FILTER(Processed_CN_HK[Value], YEAR(Processed_CN_HK[Date])=2020) ), 3) * 100} -> 100.5 | N10: {=Processed_CN_HK[[#This Row],[Value]] / _xlfn.XLOOKUP(MIN(_xlfn._xlws.FILTER(Processed_CN_HK[Date], YEAR(Processed_CN_HK[Date])=YEAR(Processed_CN_HK[[#This Row],[Date]]))), Processed_CN_HK[Date], Processed_CN_HK[Value]) - 1} -> 0.0089544377
A11: =rawData_HousePriceIndex_HK!A11 -> 44105 | B11: =rawData_HousePriceIndex_HK!B11 -> 381.3 | C11: CN_HK | D11: HousePriceIndex | E11: 44105 | F11: 9 | G11: 383 | I11: =(B11-B10)/B10 -> -0.0046985121 | K11: =Processed_CN_HK[[#This Row],[Value]]/B10 * 100 -> 99.530149 | M11: {=ROUND( Processed_CN_HK[[#This Row],[Value]] / AVERAGE( _xlfn._xlws.FILTER(Processed_CN_HK[Value], YEAR(Processed_CN_HK[Date])=2020) ), 3) * 100} -> 100 | N11: {=Processed_CN_HK[[#This Row],[Value]] / _xlfn.XLOOKUP(MIN(_xlfn._xlws.FILTER(Processed_CN_HK[Date], YEAR(Processed_CN_HK[Date])=YEAR(Processed_CN_HK[[#This Row],[Date]]))), Processed_CN_HK[Date], Processed_CN_HK[Value]) - 1} -> 0.004213853
A12: =rawData_HousePriceIndex_HK!A12 -> 44136 | B12: =rawData_HousePriceIndex_HK!B12 -> 380.6 | C12: CN_HK | D12: HousePriceIndex | E12: 44136 | F12: 10 | G12: 381 | I12: =(B12-B11)/B11 -> -0.0018358248 | K12: =Processed_CN_HK[[#This Row],[Value]]/B11 * 100 -> 99.816418 | M12: {=ROUND( Processed_CN_HK[[#This Row],[Value]] / AVERAGE( _xlfn._xlws.FILTER(Processed_CN_HK[Value], YEAR(Processed_CN_HK[Date])=2020) ), 3) * 100} -> 99.8 | N12: {=Processed_CN_HK[[#This Row],[Value]] / _xlfn.XLOOKUP(MIN(_xlfn._xlws.FILTER(Processed_CN_HK[Date], YEAR(Processed_CN_HK[Date])=YEAR(Processed_CN_HK[[#This Row],[Date]]))), Processed_CN_HK[Date], Processed_CN_HK[Value]) - 1} -> 0.0023702923
A13: =rawData_HousePriceIndex_HK!A13 -> 44166 | B13: =rawData_HousePriceIndex_HK!B13 -> 379.9 | C13: CN_HK | D13: HousePriceIndex | E13: 44166 | F13: 11 | G13: 381 | I13: =(B13-B12)/B12 -> -0.0018392013 | K13: =Processed_CN_HK[[#This Row],[Value]]/B12 * 100 -> 99.81608 | M13: {=ROUND( Processed_CN_HK[[#This Row],[Value]] / AVERAGE( _xlfn._xlws.FILTER(Processed_CN_HK[Value], YEAR(Processed_CN_HK[Date])=2020) ), 3) * 100} -> 99.7 | N13: {=Processed_CN_HK[[#This Row],[Value]] / _xlfn.XLOOKUP(MIN(_xlfn._xlws.FILTER(Processed_CN_HK[Date], YEAR(Processed_CN_HK[Date])=YEAR(Processed_CN_HK[[#This Row],[Date]]))), Processed_CN_HK[Date], Processed_CN_HK[Value]) - 1} -> 0.00052673163
A14: =rawData_HousePriceIndex_HK!A14 -> 44197 | B14: =rawData_HousePriceIndex_HK!B14 -> 381.9 | C14: CN_HK | D14: HousePriceIndex | E14: 44197 | F14: 12 | G14: 380 | H14: 380 | I14: =(B14-B13)/B13 -> 0.0052645433 | J14: =(Processed_CN_HK[[#This Row],[Value]]-B2)/B2 -> 0.0057940479 | K14: =Processed_CN_HK[[#This Row],[Value]]/B13 * 100 -> 100.52645 | L14: =Processed_CN_HK[[#This Row],[Value]]/B2 * 100 -> 100.5794 | M14: {=ROUND( Processed_CN_HK[[#This Row],[Value]] / AVERAGE( _xlfn._xlws.FILTER(Processed_CN_HK[Value], YEAR(Processed_CN_HK[Date])=2020) ), 3) * 100} -> 100.2 | N14: {=Processed_CN_HK[[#This Row],[Value]] / _xlfn.XLOOKUP(MIN(_xlfn._xlws.FILTER(Processed_CN_HK[Date], YEAR(Processed_CN_HK[Date])=YEAR(Processed_CN_HK[[#This Row],[Date]]))), Processed_CN_HK[Date], Processed_CN_HK[Value]) - 1} -> 0
A15: =rawData_HousePriceIndex_HK!A15 -> 44228 | B15: =rawData_HousePriceIndex_HK!B15 -> 384.9 | C15: CN_HK | D15: HousePriceIndex | E15: 44228 | F15: 13 | G15: 382 | H15: 373 | I15: =(B15-B14)/B14 -> 0.0078554595 | J15: =(Processed_CN_HK[[#This Row],[Value]]-B3)/B3 -> 0.030798072 | K15: =Processed_CN_HK[[#This Row],[Value]]/B14 * 100 -> 100.78555 | L15: =Processed_CN_HK[[#This Row],[Value]]/B3 * 100 -> 103.07981 | M15: {=ROUND( Processed_CN_HK[[#This Row],[Value]] / AVERAGE( _xlfn._xlws.FILTER(Processed_CN_HK[Value], YEAR(Processed_CN_HK[Date])=2020) ), 3) * 100} -> 101 | N15: {=Processed_CN_HK[[#This Row],[Value]] / _xlfn.XLOOKUP(MIN(_xlfn._xlws.FILTER(Processed_CN_HK[Date], YEAR(Processed_CN_HK[Date])=YEAR(Processed_CN_HK[[#This Row],[Date]]))), Processed_CN_HK[Date], Processed_CN_HK[Value]) - 1} -> 0.0078554595
A16: =rawData_HousePriceIndex_HK!A16 -> 44256 | B16: =rawData_HousePriceIndex_HK!B16 -> 389.6 | C16: CN_HK | D16: HousePriceIndex | E16: 44256 | F16: 14 | G16: 385 | H16: 378 | I16: =(B16-B15)/B15 -> 0.012210964 | J16: =(Processed_CN_HK[[#This Row],[Value]]-B4)/B4 -> 0.029598309 | K16: =Processed_CN_HK[[#This Row],[Value]]/B15 * 100 -> 101.2211 | L16: =Processed_CN_HK[[#This Row],[Value]]/B4 * 100 -> 102.95983 | M16: {=ROUND( Processed_CN_HK[[#This Row],[Value]] / AVERAGE( _xlfn._xlws.FILTER(Processed_CN_HK[Value], YEAR(Processed_CN_HK[Date])=2020) ), 3) * 100} -> 102.2 | N16: {=Processed_CN_HK[[#This Row],[Value]] / _xlfn.XLOOKUP(MIN(_xlfn._xlws.FILTER(Processed_CN_HK[Date], YEAR(Processed_CN_HK[Date])=YEAR(Processed_CN_HK[[#This Row],[Date]]))), Processed_CN_HK[Date], Processed_CN_HK[Value]) - 1} -> 0.020162346
A17: =rawData_HousePriceIndex_HK!A17 -> 44287 | B17: =rawData_HousePriceIndex_HK!B17 -> 391 | C17: CN_HK | D17: HousePriceIndex | E17: 44287 | F17: 15 | G17: 390 | H17: 378 | I17: =(B17-B16)/B16 -> 0.0035934292 | J17: =(Processed_CN_HK[[#This Row],[Value]]-B5)/B5 -> 0.035761589 | K17: =Processed_CN_HK[[#This Row],[Value]]/B16 * 100 -> 100.35934 | L17: =Processed_CN_HK[[#This Row],[Value]]/B5 * 100 -> 103.57616 | M17: {=ROUND( Processed_CN_HK[[#This Row],[Value]] / AVERAGE( _xlfn._xlws.FILTER(Processed_CN_HK[Value], YEAR(Processed_CN_HK[Date])=2020) ), 3) * 100} -> 102.6 | N17: {=Processed_CN_HK[[#This Row],[Value]] / _xlfn.XLOOKUP(MIN(_xlfn._xlws.FILTER(Processed_CN_HK[Date], YEAR(Processed_CN_HK[Date])=YEAR(Processed_CN_HK[[#This Row],[Date]]))), Processed_CN_HK[Date], Processed_CN_HK[Value]) - 1} -> 0.023828227
A18: =rawData_HousePriceIndex_HK!A18 -> 44317 | B18: =rawData_HousePriceIndex_HK!B18 -> 393.9 | C18: CN_HK | D18: HousePriceIndex | E18: 44317 | F18: 16 | G18: 391 | H18: 386 | I18: =(B18-B17)/B17 -> 0.0074168798 | J18: =(Processed_CN_HK[[#This Row],[Value]]-B6)/B6 -> 0.02020202 | K18: =Processed_CN_HK[[#This Row],[Value]]/B17 * 100 -> 100.74169 | L18: =Processed_CN_HK[[#This Row],[Value]]/B6 * 100 -> 102.0202 | M18: {=ROUND( Processed_CN_HK[[#This Row],[Value]] / AVERAGE( _xlfn._xlws.FILTER(Processed_CN_HK[Value], YEAR(Processed_CN_HK[Date])=2020) ), 3) * 100} -> 103.3 | N18: {=Processed_CN_HK[[#This Row],[Value]] / _xlfn.XLOOKUP(MIN(_xlfn._xlws.FILTER(Processed_CN_HK[Date], YEAR(Processed_CN_HK[Date])=YEAR(Processed_CN_HK[[#This Row],[Date]]))), Processed_CN_HK[Date], Processed_CN_HK[Value]) - 1} -> 0.031421838
A19: =rawData_HousePriceIndex_HK!A19 -> 44348 | B19: =rawData_HousePriceIndex_HK!B19 -> 394 | C19: CN_HK | D19: HousePriceIndex | E19: 44348 | F19: 17 | G19: 394 | H19: 387 | I19: =(B19-B18)/B18 -> 0.00025387154 | J19: =(Processed_CN_HK[[#This Row],[Value]]-B7)/B7 -> 0.018877683 | K19: =Processed_CN_HK[[#This Row],[Value]]/B18 * 100 -> 100.02539 | L19: =Processed_CN_HK[[#This Row],[Value]]/B7 * 100 -> 101.88777 | M19: {=ROUND( Processed_CN_HK[[#This Row],[Value]] / AVERAGE( _xlfn._xlws.FILTER(Processed_CN_HK[Value], YEAR(Processed_CN_HK[Date])=2020) ), 3) * 100} -> 103.4 | N19: {=Processed_CN_HK[[#This Row],[Value]] / _xlfn.XLOOKUP(MIN(_xlfn._xlws.FILTER(Processed_CN_HK[Date], YEAR(Processed_CN_HK[Date])=YEAR(Processed_CN_HK[[#This Row],[Date]]))), Processed_CN_HK[Date], Processed_CN_HK[Value]) - 1} -> 0.031683687
A20: =rawData_HousePriceIndex_HK!A20 -> 44378 | B20: =rawData_HousePriceIndex_HK!B20 -> 398 | C20: CN_HK | D20: HousePriceIndex | E20: 44378 | F20: 18 | G20: 394 | H20: 385 | I20: =(B20-B19)/B19 -> 0.010152284 | J20: =(Processed_CN_HK[[#This Row],[Value]]-B8)/B8 -> 0.032693306 | K20: =Processed_CN_HK[[#This Row],[Value]]/B19 * 100 -> 101.01523 | L20: =Processed_CN_HK[[#This Row],[Value]]/B8 * 100 -> 103.26933 | M20: {=ROUND( Processed_CN_HK[[#This Row],[Value]] / AVERAGE( _xlfn._xlws.FILTER(Processed_CN_HK[Value], YEAR(Processed_CN_HK[Date])=2020) ), 3) * 100} -> 104.4 | N20: {=Processed_CN_HK[[#This Row],[Value]] / _xlfn.XLOOKUP(MIN(_xlfn._xlws.FILTER(Processed_CN_HK[Date], YEAR(Processed_CN_HK[Date])=YEAR(Processed_CN_HK[[#This Row],[Date]]))), Processed_CN_HK[Date], Processed_CN_HK[Value]) - 1} -> 0.042157633
A21: =rawData_HousePriceIndex_HK!A21 -> 44409 | B21: =rawData_HousePriceIndex_HK!B21 -> 397.5 | C21: CN_HK | D21: HousePriceIndex | E21: 44409 | F21: 19 | G21: 398 | H21: 382 | I21: =(B21-B20)/B20 -> -0.0012562814 | J21: =(Processed_CN_HK[[#This Row],[Value]]-B9)/B9 -> 0.040575916 | K21: =Processed_CN_HK[[#This Row],[Value]]/B20 * 100 -> 99.874372 | L21: =Processed_CN_HK[[#This Row],[Value]]/B9 * 100 -> 104.05759 | M21: {=ROUND( Processed_CN_HK[[#This Row],[Value]] / AVERAGE( _xlfn._xlws.FILTER(Processed_CN_HK[Value], YEAR(Processed_CN_HK[Date])=2020) ), 3) * 100} -> 104.3 | N21: {=Processed_CN_HK[[#This Row],[Value]] / _xlfn.XLOOKUP(MIN(_xlfn._xlws.FILTER(Processed_CN_HK[Date], YEAR(Processed_CN_HK[Date])=YEAR(Processed_CN_HK[[#This Row],[Date]]))), Processed_CN_HK[Date], Processed_CN_HK[Value]) - 1} -> 0.04084839
A22: =rawData_HousePriceIndex_HK!A22 -> 44440 | B22: =rawData_HousePriceIndex_HK!B22 -> 398.1 | C22: CN_HK | D22: HousePriceIndex | E22: 44440 | F22: 20 | G22: 398 | H22: 383 | I22: =(B22-B21)/B21 -> 0.001509434 | J22: =(Processed_CN_HK[[#This Row],[Value]]-B10)/B10 -> 0.039154268 | K22: =Processed_CN_HK[[#This Row],[Value]]/B21 * 100 -> 100.15094 | L22: =Processed_CN_HK[[#This Row],[Value]]/B10 * 100 -> 103.91543 | M22: {=ROUND( Processed_CN_HK[[#This Row],[Value]] / AVERAGE( _xlfn._xlws.FILTER(Processed_CN_HK[Value], YEAR(Processed_CN_HK[Date])=2020) ), 3) * 100} -> 104.4 | N22: {=Processed_CN_HK[[#This Row],[Value]] / _xlfn.XLOOKUP(MIN(_xlfn._xlws.FILTER(Processed_CN_HK[Date], YEAR(Processed_CN_HK[Date])=YEAR(Processed_CN_HK[[#This Row],[Date]]))), Processed_CN_HK[Date], Processed_CN_HK[Value]) - 1} -> 0.042419482
A23: =rawData_HousePriceIndex_HK!A23 -> 44470 | B23: =rawData_HousePriceIndex_HK!B23 -> 396 | C23: CN_HK | D23: HousePriceIndex | E23: 44470 | F23: 21 | G23: 398 | H23: 381 | I23: =(B23-B22)/B22 -> -0.0052750565 | J23: =(Processed_CN_HK[[#This Row],[Value]]-B11)/B11 -> 0.038552321 | K23: =Processed_CN_HK[[#This Row],[Value]]/B22 * 100 -> 99.472494 | L23: =Processed_CN_HK[[#This Row],[Value]]/B11 * 100 -> 103.85523 | M23: {=ROUND( Processed_CN_HK[[#This Row],[Value]] / AVERAGE( _xlfn._xlws.FILTER(Processed_CN_HK[Value], YEAR(Processed_CN_HK[Date])=2020) ), 3) * 100} -> 103.9 | N23: {=Processed_CN_HK[[#This Row],[Value]] / _xlfn.XLOOKUP(MIN(_xlfn._xlws.FILTER(Processed_CN_HK[Date], YEAR(Processed_CN_HK[Date])=YEAR(Processed_CN_HK[[#This Row],[Date]]))), Processed_CN_HK[Date], Processed_CN_HK[Value]) - 1} -> 0.03692066
A24: =rawData_HousePriceIndex_HK!A24 -> 44501 | B24: =rawData_HousePriceIndex_HK!B24 -> 393.6 | C24: CN_HK | D24: HousePriceIndex | E24: 44501 | F24: 22 | G24: 396 | H24: 381 | I24: =(B24-B23)/B23 -> -0.0060606061 | J24: =(Processed_CN_HK[[#This Row],[Value]]-B12)/B12 -> 0.034156595 | K24: =Processed_CN_HK[[#This Row],[Value]]/B23 * 100 -> 99.393939 | L24: =Processed_CN_HK[[#This Row],[Value]]/B12 * 100 -> 103.41566 | M24: {=ROUND( Processed_CN_HK[[#This Row],[Value]] / AVERAGE( _xlfn._xlws.FILTER(Processed_CN_HK[Value], YEAR(Processed_CN_HK[Date])=2020) ), 3) * 100} -> 103.3 | N24: {=Processed_CN_HK[[#This Row],[Value]] / _xlfn.XLOOKUP(MIN(_xlfn._xlws.FILTER(Processed_CN_HK[Date], YEAR(Processed_CN_HK[Date])=YEAR(Processed_CN_HK[[#This Row],[Date]]))), Processed_CN_HK[Date], Processed_CN_HK[Value]) - 1} -> 0.030636292
A25: =rawData_HousePriceIndex_HK!A25 -> 44531 | B25: =rawData_HousePriceIndex_HK!B25 -> 393.9 | C25: CN_HK | D25: HousePriceIndex | E25: 44531 | F25: 23 | G25: 394 | H25: 380 | I25: =(B25-B24)/B24 -> 0.00076219512 | J25: =(Processed_CN_HK[[#This Row],[Value]]-B13)/B13 -> 0.036851803 | K25: =Processed_CN_HK[[#This Row],[Value]]/B24 * 100 -> 100.07622 | L25: =Processed_CN_HK[[#This Row],[Value]]/B13 * 100 -> 103.68518 | M25: {=ROUND( Processed_CN_HK[[#This Row],[Value]] / AVERAGE( _xlfn._xlws.FILTER(Processed_CN_HK[Value], YEAR(Processed_CN_HK[Date])=2020) ), 3) * 100} -> 103.3 | N25: {=Processed_CN_HK[[#This Row],[Value]] / _xlfn.XLOOKUP(MIN(_xlfn._xlws.FILTER(Processed_CN_HK[Date], YEAR(Processed_CN_HK[Date])=YEAR(Processed_CN_HK[[#This Row],[Date]]))), Processed_CN_HK[Date], Processed_CN_HK[Value]) - 1} -> 0.031421838
... A69: =rawData_HousePriceIndex_HK!A69 -> 45870 | B69: =rawData_HousePriceIndex_HK!B69 -> 288.7 | C69: CN_HK | D69: HousePriceIndex | E69: 45870 | F69: 67 | G69: 288 | H69: 292 | I69: =(B69-B68)/B68 -> 0.0020826102 | J69: =(Processed_CN_HK[[#This Row],[Value]]-B57)/B57 -> -0.01130137 | K69: =Processed_CN_HK[[#This Row],[Value]]/B68 * 100 -> 100.20826 | L69: =Processed_CN_HK[[#This Row],[Value]]/B57 * 100 -> 98.869863 | M69: {=ROUND( Processed_CN_HK[[#This Row],[Value]] / AVERAGE( _xlfn._xlws.FILTER(Processed_CN_HK[Value], YEAR(Processed_CN_HK[Date])=2020) ), 3) * 100} -> 75.7 | N69: {=Processed_CN_HK[[#This Row],[Value]] / _xlfn.XLOOKUP(MIN(_xlfn._xlws.FILTER(Processed_CN_HK[Date], YEAR(Processed_CN_HK[Date])=YEAR(Processed_CN_HK[[#This Row],[Date]]))), Processed_CN_HK[Date], Processed_CN_HK[Value]) - 1} -> 0.0052228412
A70: =rawData_HousePriceIndex_HK!A70 -> 45901 | B70: =rawData_HousePriceIndex_HK!B70 -> 293.4 | C70: CN_HK | I70: =(B70-B69)/B69 -> 0.016279875 | J70: =(Processed_CN_HK[[#This Row],[Value]]-B58)/B58 -> 0.019103856 | K70: =Processed_CN_HK[[#This Row],[Value]]/B69 * 100 -> 101.62799 | L70: =Processed_CN_HK[[#This Row],[Value]]/B58 * 100 -> 101.91039 | M70: {=ROUND( Processed_CN_HK[[#This Row],[Value]] / AVERAGE( _xlfn._xlws.FILTER(Processed_CN_HK[Value], YEAR(Processed_CN_HK[Date])=2020) ), 3) * 100} -> 77 | N70: {=Processed_CN_HK[[#This Row],[Value]] / _xlfn.XLOOKUP(MIN(_xlfn._xlws.FILTER(Processed_CN_HK[Date], YEAR(Processed_CN_HK[Date])=YEAR(Processed_CN_HK[[#This Row],[Date]]))), Processed_CN_HK[Date], Processed_CN_HK[Value]) - 1} -> 0.021587744
A71: =rawData_HousePriceIndex_HK!A71 -> 45931 | B71: =rawData_HousePriceIndex_HK!B71 -> 294.9 | C71: CN_HK | D71: HousePriceIndex | E71: 45871 | F71: 67 | G71: 288 | H71: 292 | I71: =(B71-B70)/B70 -> 0.0051124744 | J71: =(Processed_CN_HK[[#This Row],[Value]]-B59)/B59 -> 0.013402062 | K71: =Processed_CN_HK[[#This Row],[Value]]/B70 * 100 -> 100.51125 | L71: =Processed_CN_HK[[#This Row],[Value]]/B59 * 100 -> 101.34021 | M71: {=ROUND( Processed_CN_HK[[#This Row],[Value]] / AVERAGE( _xlfn._xlws.FILTER(Processed_CN_HK[Value], YEAR(Processed_CN_HK[Date])=2020) ), 3) * 100} -> 77.4 | N71: {=Processed_CN_HK[[#This Row],[Value]] / _xlfn.XLOOKUP(MIN(_xlfn._xlws.FILTER(Processed_CN_HK[Date], YEAR(Processed_CN_HK[Date])=YEAR(Processed_CN_HK[[#This Row],[Date]]))), Processed_CN_HK[Date], Processed_CN_HK[Value]) - 1} -> 0.026810585
A72: =rawData_HousePriceIndex_HK!A72 -> 45962 | B72: =rawData_HousePriceIndex_HK!B72 -> 298.7 | C72: CN_HK | I72: =(B72-B71)/B71 -> 0.012885724 | J72: =(Processed_CN_HK[[#This Row],[Value]]-B60)/B60 -> 0.024699828 | K72: =Processed_CN_HK[[#This Row],[Value]]/B71 * 100 -> 101.28857 | L72: =Processed_CN_HK[[#This Row],[Value]]/B60 * 100 -> 102.46998 | M72: {=ROUND( Processed_CN_HK[[#This Row],[Value]] / AVERAGE( _xlfn._xlws.FILTER(Processed_CN_HK[Value], YEAR(Processed_CN_HK[Date])=2020) ), 3) * 100} -> 78.4 | N72: {=Processed_CN_HK[[#This Row],[Value]] / _xlfn.XLOOKUP(MIN(_xlfn._xlws.FILTER(Processed_CN_HK[Date], YEAR(Processed_CN_HK[Date])=YEAR(Processed_CN_HK[[#This Row],[Date]]))), Processed_CN_HK[Date], Processed_CN_HK[Value]) - 1} -> 0.040041783
A73: =rawData_HousePriceIndex_HK!A73 -> 45992 | B73: =rawData_HousePriceIndex_HK!B73 -> 299.6 | C73: CN_HK | D73: HousePriceIndex | E73: 45872 | F73: 67 | G73: 288 | H73: 292 | I73: =(B73-B72)/B72 -> 0.0030130566 | J73: =(Processed_CN_HK[[#This Row],[Value]]-B61)/B61 -> 0.035961272 | K73: =Processed_CN_HK[[#This Row],[Value]]/B72 * 100 -> 100.30131 | L73: =Processed_CN_HK[[#This Row],[Value]]/B61 * 100 -> 103.59613 | M73: {=ROUND( Processed_CN_HK[[#This Row],[Value]] / AVERAGE( _xlfn._xlws.FILTER(Processed_CN_HK[Value], YEAR(Processed_CN_HK[Date])=2020) ), 3) * 100} -> 78.6 | N73: {=Processed_CN_HK[[#This Row],[Value]] / _xlfn.XLOOKUP(MIN(_xlfn._xlws.FILTER(Processed_CN_HK[Date], YEAR(Processed_CN_HK[Date])=YEAR(Processed_CN_HK[[#This Row],[Date]]))), Processed_CN_HK[Date], Processed_CN_HK[Value]) - 1} -> 0.043175487
A74: =rawData_HousePriceIndex_HK!A74 -> 46023 | B74: =rawData_HousePriceIndex_HK!B74 -> 303 | C74: CN_HK | I74: =(B74-B73)/B73 -> 0.011348465 | J74: =(Processed_CN_HK[[#This Row],[Value]]-B62)/B62 -> 0.055013928 | K74: =Processed_CN_HK[[#This Row],[Value]]/B73 * 100 -> 101.13485 | L74: =Processed_CN_HK[[#This Row],[Value]]/B62 * 100 -> 105.50139 | M74: {=ROUND( Processed_CN_HK[[#This Row],[Value]] / AVERAGE( _xlfn._xlws.FILTER(Processed_CN_HK[Value], YEAR(Processed_CN_HK[Date])=2020) ), 3) * 100} -> 79.5 | N74: {=Processed_CN_HK[[#This Row],[Value]] / _xlfn.XLOOKUP(MIN(_xlfn._xlws.FILTER(Processed_CN_HK[Date], YEAR(Processed_CN_HK[Date])=YEAR(Processed_CN_HK[[#This Row],[Date]]))), Processed_CN_HK[Date], Processed_CN_HK[Value]) - 1} -> 0
A75: =rawData_HousePriceIndex_HK!A75 -> 46054 | B75: =rawData_HousePriceIndex_HK!B75 -> 308.5 | C75: CN_HK | D75: HousePriceIndex | E75: 45873 | F75: 67 | G75: 288 | H75: 292 | I75: =(B75-B74)/B74 -> 0.018151815 | J75: =(Processed_CN_HK[[#This Row],[Value]]-B63)/B63 -> 0.080182073 | K75: =Processed_CN_HK[[#This Row],[Value]]/B74 * 100 -> 101.81518 | L75: =Processed_CN_HK[[#This Row],[Value]]/B63 * 100 -> 108.01821 | M75: {=ROUND( Processed_CN_HK[[#This Row],[Value]] / AVERAGE( _xlfn._xlws.FILTER(Processed_CN_HK[Value], YEAR(Processed_CN_HK[Date])=2020) ), 3) * 100} -> 80.9 | N75: {=Processed_CN_HK[[#This Row],[Value]] / _xlfn.XLOOKUP(MIN(_xlfn._xlws.FILTER(Processed_CN_HK[Date], YEAR(Processed_CN_HK[Date])=YEAR(Processed_CN_HK[[#This Row],[Date]]))), Processed_CN_HK[Date], Processed_CN_HK[Value]) - 1} -> 0.018151815
A76: =rawData_HousePriceIndex_HK!A76 -> 46082 | B76: =rawData_HousePriceIndex_HK!B76 -> 312.8 | C76: CN_HK | I76: =(B76-B75)/B75 -> 0.013938412 | J76: =(Processed_CN_HK[[#This Row],[Value]]-B64)/B64 -> 0.097929098 | K76: =Processed_CN_HK[[#This Row],[Value]]/B75 * 100 -> 101.39384 | L76: =Processed_CN_HK[[#This Row],[Value]]/B64 * 100 -> 109.79291 | M76: {=ROUND( Processed_CN_HK[[#This Row],[Value]] / AVERAGE( _xlfn._xlws.FILTER(Processed_CN_HK[Value], YEAR(Processed_CN_HK[Date])=2020) ), 3) * 100} -> 82.1 | N76: {=Processed_CN_HK[[#This Row],[Value]] / _xlfn.XLOOKUP(MIN(_xlfn._xlws.FILTER(Processed_CN_HK[Date], YEAR(Processed_CN_HK[Date])=YEAR(Processed_CN_HK[[#This Row],[Date]]))), Processed_CN_HK[Date], Processed_CN_HK[Value]) - 1} -> 0.032343234
A77: =rawData_HousePriceIndex_HK!A77 -> 46113 | B77: =rawData_HousePriceIndex_HK!B77 -> 316.6 | C77: CN_HK | D77: HousePriceIndex | E77: 45874 | F77: 67 | G77: 288 | H77: 292 | I77: =(B77-B76)/B76 -> 0.012148338 | J77: =(Processed_CN_HK[[#This Row],[Value]]-B65)/B65 -> 0.10506108 | K77: =Processed_CN_HK[[#This Row],[Value]]/B76 * 100 -> 101.21483 | L77: =Processed_CN_HK[[#This Row],[Value]]/B65 * 100 -> 110.50611 | M77: {=ROUND( Processed_CN_HK[[#This Row],[Value]] / AVERAGE( _xlfn._xlws.FILTER(Processed_CN_HK[Value], YEAR(Processed_CN_HK[Date])=2020) ), 3) * 100} -> 83.1 | N77: {=Processed_CN_HK[[#This Row],[Value]] / _xlfn.XLOOKUP(MIN(_xlfn._xlws.FILTER(Processed_CN_HK[Date], YEAR(Processed_CN_HK[Date])=YEAR(Processed_CN_HK[[#This Row],[Date]]))), Processed_CN_HK[Date], Processed_CN_HK[Value]) - 1} -> 0.044884488

Sheet Processed_HousePriceIndex_US_CA
A1: Date | B1: Value | C1: Region | D1: Type | E1: ReleaseDate(ObservationDate) | F1: 索引 | G1: Price_Prev_Month | H1: Price_Prev_Year | I1: MoM | J1: YoY | K1: 上月=100 | L1: 上年同月=100 | M1: 2020平均值 = 100 | N1: YTD(%)
A2: =rawData_HousePriceIndex_US!A2 -> 43831 | B2: =rawData_HousePriceIndex_US!B2 -> 272.614 | C2: US_CA | D2: HousePriceIndex | E2: 43831 | F2: 0 | M2: {=ROUND( Processed_US_CA[[#This Row],[Value]] / AVERAGE( _xlfn._xlws.FILTER(Processed_US_CA[Value], YEAR(Processed_US_CA[Date])=2020) ), 3) * 100} -> 97.7 | N2: {=Processed_US_CA[[#This Row],[Value]] / _xlfn.XLOOKUP(MIN(_xlfn._xlws.FILTER(Processed_US_CA[Date], YEAR(Processed_US_CA[Date])=YEAR(Processed_US_CA[[#This Row],[Date]]))), Processed_US_CA[Date], Processed_US_CA[Value]) - 1} -> 0
